INFO:uvicorn.error:Started server process [1688]
INFO:uvicorn.error:Waiting for application startup.
INFO:uvicorn.error:Application startup complete.
INFO:uvicorn.error:Uvicorn running on http://0.0.0.0:9090 (Press CTRL+C to quit)
INFO:root:{"datetime": "d.06.2024-01:12:48", "filename": "image0027.jpg"}
INFO:uvicorn.error:Started server process [13884]
INFO:uvicorn.error:Waiting for application startup.
INFO:uvicorn.error:Application startup complete.
INFO:uvicorn.error:Uvicorn running on http://0.0.0.0:9090 (Press CTRL+C to quit)
INFO:uvicorn.error:Started server process [6312]
INFO:uvicorn.error:Waiting for application startup.
INFO:uvicorn.error:Application startup complete.
INFO:uvicorn.error:Uvicorn running on http://0.0.0.0:9090 (Press CTRL+C to quit)
INFO:uvicorn.error:Started server process [15616]
INFO:uvicorn.error:Waiting for application startup.
INFO:uvicorn.error:Application startup complete.
INFO:uvicorn.error:Uvicorn running on http://0.0.0.0:9090 (Press CTRL+C to quit)
INFO:root:{"datetime": "18.06.2024-07:55:50", "filename": "image0022.jpg"}
INFO:uvicorn.error:Started server process [7296]
INFO:uvicorn.error:Waiting for application startup.
INFO:uvicorn.error:Application startup complete.
INFO:uvicorn.error:Uvicorn running on http://0.0.0.0:9090 (Press CTRL+C to quit)
ERROR:uvicorn.error:Exception in ASGI application
Traceback (most recent call last):
  File "C:\Users\AHTOH\AppData\Local\Packages\PythonSoftwareFoundation.Python.3.10_qbz5n2kfra8p0\LocalCache\local-packages\Python310\site-packages\uvicorn\protocols\http\h11_impl.py", line 403, in run_asgi
    result = await app(self.scope, self.receive, self.send)
  File "C:\Users\AHTOH\AppData\Local\Packages\PythonSoftwareFoundation.Python.3.10_qbz5n2kfra8p0\LocalCache\local-packages\Python310\site-packages\uvicorn\middleware\proxy_headers.py", line 78, in __call__
    return await self.app(scope, receive, send)
  File "C:\Users\AHTOH\AppData\Local\Packages\PythonSoftwareFoundation.Python.3.10_qbz5n2kfra8p0\LocalCache\local-packages\Python310\site-packages\fastapi\applications.py", line 269, in __call__
    await super().__call__(scope, receive, send)
  File "C:\Users\AHTOH\AppData\Local\Packages\PythonSoftwareFoundation.Python.3.10_qbz5n2kfra8p0\LocalCache\local-packages\Python310\site-packages\starlette\applications.py", line 124, in __call__
    await self.middleware_stack(scope, receive, send)
  File "C:\Users\AHTOH\AppData\Local\Packages\PythonSoftwareFoundation.Python.3.10_qbz5n2kfra8p0\LocalCache\local-packages\Python310\site-packages\starlette\middleware\errors.py", line 184, in __call__
    raise exc
  File "C:\Users\AHTOH\AppData\Local\Packages\PythonSoftwareFoundation.Python.3.10_qbz5n2kfra8p0\LocalCache\local-packages\Python310\site-packages\starlette\middleware\errors.py", line 162, in __call__
    await self.app(scope, receive, _send)
  File "C:\Users\AHTOH\AppData\Local\Packages\PythonSoftwareFoundation.Python.3.10_qbz5n2kfra8p0\LocalCache\local-packages\Python310\site-packages\starlette\exceptions.py", line 93, in __call__
    raise exc
  File "C:\Users\AHTOH\AppData\Local\Packages\PythonSoftwareFoundation.Python.3.10_qbz5n2kfra8p0\LocalCache\local-packages\Python310\site-packages\starlette\exceptions.py", line 82, in __call__
    await self.app(scope, receive, sender)
  File "C:\Users\AHTOH\AppData\Local\Packages\PythonSoftwareFoundation.Python.3.10_qbz5n2kfra8p0\LocalCache\local-packages\Python310\site-packages\fastapi\middleware\asyncexitstack.py", line 21, in __call__
    raise e
  File "C:\Users\AHTOH\AppData\Local\Packages\PythonSoftwareFoundation.Python.3.10_qbz5n2kfra8p0\LocalCache\local-packages\Python310\site-packages\fastapi\middleware\asyncexitstack.py", line 18, in __call__
    await self.app(scope, receive, send)
  File "C:\Users\AHTOH\AppData\Local\Packages\PythonSoftwareFoundation.Python.3.10_qbz5n2kfra8p0\LocalCache\local-packages\Python310\site-packages\starlette\routing.py", line 670, in __call__
    await route.handle(scope, receive, send)
  File "C:\Users\AHTOH\AppData\Local\Packages\PythonSoftwareFoundation.Python.3.10_qbz5n2kfra8p0\LocalCache\local-packages\Python310\site-packages\starlette\routing.py", line 266, in handle
    await self.app(scope, receive, send)
  File "C:\Users\AHTOH\AppData\Local\Packages\PythonSoftwareFoundation.Python.3.10_qbz5n2kfra8p0\LocalCache\local-packages\Python310\site-packages\starlette\routing.py", line 65, in app
    response = await func(request)
  File "C:\Users\AHTOH\AppData\Local\Packages\PythonSoftwareFoundation.Python.3.10_qbz5n2kfra8p0\LocalCache\local-packages\Python310\site-packages\fastapi\routing.py", line 227, in app
    raw_response = await run_endpoint_function(
  File "C:\Users\AHTOH\AppData\Local\Packages\PythonSoftwareFoundation.Python.3.10_qbz5n2kfra8p0\LocalCache\local-packages\Python310\site-packages\fastapi\routing.py", line 160, in run_endpoint_function
    return await dependant.call(**values)
  File "c:\work\git\101dalmatinas\main.py", line 15, in upload_file
    logging.info(json.dumps(log_msg, ensure_ascii=False,))
NameError: name 'log_msg' is not defined
ERROR:uvicorn.error:Exception in ASGI application
Traceback (most recent call last):
  File "C:\Users\AHTOH\AppData\Local\Packages\PythonSoftwareFoundation.Python.3.10_qbz5n2kfra8p0\LocalCache\local-packages\Python310\site-packages\uvicorn\protocols\http\h11_impl.py", line 403, in run_asgi
    result = await app(self.scope, self.receive, self.send)
  File "C:\Users\AHTOH\AppData\Local\Packages\PythonSoftwareFoundation.Python.3.10_qbz5n2kfra8p0\LocalCache\local-packages\Python310\site-packages\uvicorn\middleware\proxy_headers.py", line 78, in __call__
    return await self.app(scope, receive, send)
  File "C:\Users\AHTOH\AppData\Local\Packages\PythonSoftwareFoundation.Python.3.10_qbz5n2kfra8p0\LocalCache\local-packages\Python310\site-packages\fastapi\applications.py", line 269, in __call__
    await super().__call__(scope, receive, send)
  File "C:\Users\AHTOH\AppData\Local\Packages\PythonSoftwareFoundation.Python.3.10_qbz5n2kfra8p0\LocalCache\local-packages\Python310\site-packages\starlette\applications.py", line 124, in __call__
    await self.middleware_stack(scope, receive, send)
  File "C:\Users\AHTOH\AppData\Local\Packages\PythonSoftwareFoundation.Python.3.10_qbz5n2kfra8p0\LocalCache\local-packages\Python310\site-packages\starlette\middleware\errors.py", line 184, in __call__
    raise exc
  File "C:\Users\AHTOH\AppData\Local\Packages\PythonSoftwareFoundation.Python.3.10_qbz5n2kfra8p0\LocalCache\local-packages\Python310\site-packages\starlette\middleware\errors.py", line 162, in __call__
    await self.app(scope, receive, _send)
  File "C:\Users\AHTOH\AppData\Local\Packages\PythonSoftwareFoundation.Python.3.10_qbz5n2kfra8p0\LocalCache\local-packages\Python310\site-packages\starlette\exceptions.py", line 93, in __call__
    raise exc
  File "C:\Users\AHTOH\AppData\Local\Packages\PythonSoftwareFoundation.Python.3.10_qbz5n2kfra8p0\LocalCache\local-packages\Python310\site-packages\starlette\exceptions.py", line 82, in __call__
    await self.app(scope, receive, sender)
  File "C:\Users\AHTOH\AppData\Local\Packages\PythonSoftwareFoundation.Python.3.10_qbz5n2kfra8p0\LocalCache\local-packages\Python310\site-packages\fastapi\middleware\asyncexitstack.py", line 21, in __call__
    raise e
  File "C:\Users\AHTOH\AppData\Local\Packages\PythonSoftwareFoundation.Python.3.10_qbz5n2kfra8p0\LocalCache\local-packages\Python310\site-packages\fastapi\middleware\asyncexitstack.py", line 18, in __call__
    await self.app(scope, receive, send)
  File "C:\Users\AHTOH\AppData\Local\Packages\PythonSoftwareFoundation.Python.3.10_qbz5n2kfra8p0\LocalCache\local-packages\Python310\site-packages\starlette\routing.py", line 670, in __call__
    await route.handle(scope, receive, send)
  File "C:\Users\AHTOH\AppData\Local\Packages\PythonSoftwareFoundation.Python.3.10_qbz5n2kfra8p0\LocalCache\local-packages\Python310\site-packages\starlette\routing.py", line 266, in handle
    await self.app(scope, receive, send)
  File "C:\Users\AHTOH\AppData\Local\Packages\PythonSoftwareFoundation.Python.3.10_qbz5n2kfra8p0\LocalCache\local-packages\Python310\site-packages\starlette\routing.py", line 65, in app
    response = await func(request)
  File "C:\Users\AHTOH\AppData\Local\Packages\PythonSoftwareFoundation.Python.3.10_qbz5n2kfra8p0\LocalCache\local-packages\Python310\site-packages\fastapi\routing.py", line 227, in app
    raw_response = await run_endpoint_function(
  File "C:\Users\AHTOH\AppData\Local\Packages\PythonSoftwareFoundation.Python.3.10_qbz5n2kfra8p0\LocalCache\local-packages\Python310\site-packages\fastapi\routing.py", line 160, in run_endpoint_function
    return await dependant.call(**values)
  File "c:\work\git\101dalmatinas\main.py", line 15, in upload_file
    logging.info(json.dumps(log_msg, ensure_ascii=False,))
NameError: name 'log_msg' is not defined
INFO:uvicorn.error:Started server process [15424]
INFO:uvicorn.error:Waiting for application startup.
INFO:uvicorn.error:Application startup complete.
INFO:uvicorn.error:Uvicorn running on http://0.0.0.0:9090 (Press CTRL+C to quit)
INFO:root:{"datetime": "18.06.2024-08:01:50", "filename": "image0020.jpg"}
ERROR:uvicorn.error:Exception in ASGI application
Traceback (most recent call last):
  File "C:\Users\AHTOH\AppData\Local\Packages\PythonSoftwareFoundation.Python.3.10_qbz5n2kfra8p0\LocalCache\local-packages\Python310\site-packages\uvicorn\protocols\http\h11_impl.py", line 403, in run_asgi
    result = await app(self.scope, self.receive, self.send)
  File "C:\Users\AHTOH\AppData\Local\Packages\PythonSoftwareFoundation.Python.3.10_qbz5n2kfra8p0\LocalCache\local-packages\Python310\site-packages\uvicorn\middleware\proxy_headers.py", line 78, in __call__
    return await self.app(scope, receive, send)
  File "C:\Users\AHTOH\AppData\Local\Packages\PythonSoftwareFoundation.Python.3.10_qbz5n2kfra8p0\LocalCache\local-packages\Python310\site-packages\fastapi\applications.py", line 269, in __call__
    await super().__call__(scope, receive, send)
  File "C:\Users\AHTOH\AppData\Local\Packages\PythonSoftwareFoundation.Python.3.10_qbz5n2kfra8p0\LocalCache\local-packages\Python310\site-packages\starlette\applications.py", line 124, in __call__
    await self.middleware_stack(scope, receive, send)
  File "C:\Users\AHTOH\AppData\Local\Packages\PythonSoftwareFoundation.Python.3.10_qbz5n2kfra8p0\LocalCache\local-packages\Python310\site-packages\starlette\middleware\errors.py", line 184, in __call__
    raise exc
  File "C:\Users\AHTOH\AppData\Local\Packages\PythonSoftwareFoundation.Python.3.10_qbz5n2kfra8p0\LocalCache\local-packages\Python310\site-packages\starlette\middleware\errors.py", line 162, in __call__
    await self.app(scope, receive, _send)
  File "C:\Users\AHTOH\AppData\Local\Packages\PythonSoftwareFoundation.Python.3.10_qbz5n2kfra8p0\LocalCache\local-packages\Python310\site-packages\starlette\exceptions.py", line 93, in __call__
    raise exc
  File "C:\Users\AHTOH\AppData\Local\Packages\PythonSoftwareFoundation.Python.3.10_qbz5n2kfra8p0\LocalCache\local-packages\Python310\site-packages\starlette\exceptions.py", line 82, in __call__
    await self.app(scope, receive, sender)
  File "C:\Users\AHTOH\AppData\Local\Packages\PythonSoftwareFoundation.Python.3.10_qbz5n2kfra8p0\LocalCache\local-packages\Python310\site-packages\fastapi\middleware\asyncexitstack.py", line 21, in __call__
    raise e
  File "C:\Users\AHTOH\AppData\Local\Packages\PythonSoftwareFoundation.Python.3.10_qbz5n2kfra8p0\LocalCache\local-packages\Python310\site-packages\fastapi\middleware\asyncexitstack.py", line 18, in __call__
    await self.app(scope, receive, send)
  File "C:\Users\AHTOH\AppData\Local\Packages\PythonSoftwareFoundation.Python.3.10_qbz5n2kfra8p0\LocalCache\local-packages\Python310\site-packages\starlette\routing.py", line 670, in __call__
    await route.handle(scope, receive, send)
  File "C:\Users\AHTOH\AppData\Local\Packages\PythonSoftwareFoundation.Python.3.10_qbz5n2kfra8p0\LocalCache\local-packages\Python310\site-packages\starlette\routing.py", line 266, in handle
    await self.app(scope, receive, send)
  File "C:\Users\AHTOH\AppData\Local\Packages\PythonSoftwareFoundation.Python.3.10_qbz5n2kfra8p0\LocalCache\local-packages\Python310\site-packages\starlette\routing.py", line 65, in app
    response = await func(request)
  File "C:\Users\AHTOH\AppData\Local\Packages\PythonSoftwareFoundation.Python.3.10_qbz5n2kfra8p0\LocalCache\local-packages\Python310\site-packages\fastapi\routing.py", line 227, in app
    raw_response = await run_endpoint_function(
  File "C:\Users\AHTOH\AppData\Local\Packages\PythonSoftwareFoundation.Python.3.10_qbz5n2kfra8p0\LocalCache\local-packages\Python310\site-packages\fastapi\routing.py", line 160, in run_endpoint_function
    return await dependant.call(**values)
  File "c:\work\git\101dalmatinas\main.py", line 21, in upload_file
    logging.info(log_msg_finish, ensure_ascii=False,)
  File "C:\Program Files\WindowsApps\PythonSoftwareFoundation.Python.3.10_3.10.3056.0_x64__qbz5n2kfra8p0\lib\logging\__init__.py", line 2138, in info
    root.info(msg, *args, **kwargs)
  File "C:\Program Files\WindowsApps\PythonSoftwareFoundation.Python.3.10_3.10.3056.0_x64__qbz5n2kfra8p0\lib\logging\__init__.py", line 1477, in info
    self._log(INFO, msg, args, **kwargs)
TypeError: Logger._log() got an unexpected keyword argument 'ensure_ascii'
INFO:uvicorn.error:Started server process [13120]
INFO:uvicorn.error:Waiting for application startup.
INFO:uvicorn.error:Application startup complete.
INFO:uvicorn.error:Uvicorn running on http://0.0.0.0:9090 (Press CTRL+C to quit)
INFO:root:{"datetime": "18.06.2024-08:03:07", "filename": "image0019.jpg"}
INFO:root:{'datetime': '18.06.2024-08:03:08', 'res': '[{"type": "CODE128", "data": "0000093455", "orientation": "RIGHT"}, {"type": "EAN13", "data": "2107047307968", "orientation": "UP"}, {"type": "EAN13", "data": "2101041307962", "orientation": "UP"}]'}
INFO:root:{"datetime": "18.06.2024-08:05:32", "filename": "image0019.jpg"}
INFO:root:{'datetime': '18.06.2024-08:06:53', 'res': '[{"type": "CODE128", "data": "0000093455", "orientation": "RIGHT"}, {"type": "EAN13", "data": "2107047307968", "orientation": "UP"}, {"type": "EAN13", "data": "2101041307962", "orientation": "UP"}]'}
INFO:uvicorn.error:Started server process [5216]
INFO:uvicorn.error:Waiting for application startup.
INFO:uvicorn.error:Application startup complete.
INFO:uvicorn.error:Uvicorn running on http://0.0.0.0:9090 (Press CTRL+C to quit)
INFO:root:{"datetime": "18.06.2024-08:27:26", "filename": "image0018.jpg"}
INFO:root:{'datetime': '18.06.2024-08:27:37', 'res': '[{"type": "EAN13", "data": "2101041307436", "orientation": "UP"}]'}
INFO:root:{"datetime": "18.06.2024-08:28:02", "filename": "image0019.jpg"}
INFO:root:{'datetime': '18.06.2024-08:28:02', 'res': '[{"type": "CODE128", "data": "0000093455", "orientation": "RIGHT"}, {"type": "EAN13", "data": "2107047307968", "orientation": "UP"}, {"type": "EAN13", "data": "2101041307962", "orientation": "UP"}]'}
INFO:root:{"datetime": "18.06.2024-08:28:12", "filename": "image0018.jpg"}
INFO:root:{'datetime': '18.06.2024-08:28:12', 'res': '[{"type": "EAN13", "data": "2101041307436", "orientation": "UP"}]'}
INFO:root:{"datetime": "18.06.2024-08:28:28", "filename": "image0013.jpg"}
INFO:root:{'datetime': '18.06.2024-08:28:28', 'res': '[{"type": "CODE128", "data": "0000093519", "orientation": "RIGHT"}, {"type": "EAN13", "data": "2101041307306", "orientation": "UP"}]'}
INFO:root:{"datetime": "18.06.2024-08:29:01", "filename": "image0012.jpg"}
INFO:root:{'datetime': '18.06.2024-08:30:48', 'res': '[{"type": "EAN13", "data": "2101041307788", "orientation": "UP"}]'}
INFO:uvicorn.error:Started server process [12940]
INFO:uvicorn.error:Waiting for application startup.
INFO:uvicorn.error:Application startup complete.
INFO:uvicorn.error:Uvicorn running on http://0.0.0.0:9090 (Press CTRL+C to quit)
INFO:root:{"datetime": "18.06.2024-08:31:15", "filename": "image0019.jpg"}
INFO:root:{'datetime': '18.06.2024-08:31:16', 'res': '[{"type": "CODE128", "data": "0000093455", "orientation": "RIGHT"}]'}
INFO:uvicorn.error:Started server process [11100]
INFO:uvicorn.error:Waiting for application startup.
INFO:uvicorn.error:Application startup complete.
INFO:uvicorn.error:Uvicorn running on http://0.0.0.0:9090 (Press CTRL+C to quit)
INFO:root:{"datetime": "18.06.2024-08:32:13", "filename": "image0019.jpg"}
INFO:root:{'datetime': '18.06.2024-08:32:27', 'res': '[{"type": "CODE128", "data": "0000093455", "orientation": "RIGHT"}]'}
INFO:uvicorn.error:Started server process [14712]
INFO:uvicorn.error:Waiting for application startup.
INFO:uvicorn.error:Application startup complete.
INFO:uvicorn.error:Uvicorn running on http://0.0.0.0:9090 (Press CTRL+C to quit)
INFO:root:{"datetime": "18.06.2024-08:33:17", "filename": "image0019.jpg"}
INFO:root:{'datetime': '18.06.2024-08:33:18', 'res': '[{"type": "CODE128", "data": "0000093455", "orientation": "RIGHT"}, {"type": "EAN13", "data": "2101041307962", "orientation": "UP"}]'}
INFO:root:{"datetime": "18.06.2024-08:33:28", "filename": "image0018.jpg"}
INFO:root:{'datetime': '18.06.2024-08:33:28', 'res': '[{"type": "EAN13", "data": "2101041307436", "orientation": "UP"}]'}
